<?xml version="1.0" ?>
<!-- =================================================================================== -->
<!-- |    This document was autogenerated by xacro from src/bishop_ros/urdf/cleanbot.xacro | -->
<!-- |    EDITING THIS FILE BY HAND IS NOT RECOMMENDED                                 | -->
<!-- =================================================================================== -->
<!-- Copyright (C) 2020 CrossWing Inc. All rights reserved. -->
<!-- Do not copy or distribute without authorization.       -->
<!--
  Model of the Cleanbot variant of Bishop.

  Author: Helio Perroni Filho
-->
<robot name="cleanbot">
  <!-- Pre-defined material colors. -->
  <material name="Black">
    <color rgba="0.0 0.0 0.0 1.0"/>
  </material>
  <material name="White">
    <color rgba="1.0 1.0 1.0 1.0"/>
  </material>
  <material name="Grey">
    <color rgba="0.3 0.3 0.3 1.0"/>
  </material>
  <material name="DarkGrey">
    <color rgba="0.175 0.175 0.175 1.0"/>
  </material>
  <!-- Link for a coordinate frame on the floor. -->
  <link name="base_link"/>
  <link name="body">
    <visual>
      <origin rpy="0.0 0.0 0.0" xyz="0.0 0.0 0.45"/>
      <geometry>
        <mesh filename="bishop_ros/urdf/bishop.stl"/>
      </geometry>
      <material name="White"/>
    </visual>
  </link>
  <gazebo reference="body">
    <material>Gazebo/White</material>
  </gazebo>
  <link name="mobile_base">
    <inertial>
      <origin rpy="0.0 0.0 0.0" xyz="0.0 0.0 0.25"/>
      <mass value="90.0"/>
      <inertia ixx="3.5274225" ixy="0.0" ixz="0.0" iyy="3.5274225" iyz="0.0" izz="3.3048450000000003"/>
    </inertial>
    <visual>
      <origin rpy="0.0 0.0 0.0" xyz="0.0 0.0 0.25"/>
      <geometry>
        <cylinder length="0.5" radius="0.271"/>
      </geometry>
      <material name="Black"/>
    </visual>
    <collision>
      <origin rpy="0.0 0.0 0.0" xyz="0.0 0.0 0.25"/>
      <geometry>
        <cylinder length="0.5" radius="0.271"/>
      </geometry>
    </collision>
  </link>
  <gazebo reference="mobile_base">
    <material>Gazebo/Black</material>
  </gazebo>
  <link name="lower_body">
    <inertial>
      <origin rpy="0.0 0.0 0.0" xyz="0.0 0.0 0.0"/>
      <mass value="0.1"/>
      <inertia ixx="0.002937640000000001" ixy="0.0" ixz="0.0" iyy="0.002937640000000001" iyz="0.0" izz="0.002937640000000001"/>
    </inertial>
    <collision>
      <origin rpy="0.0 0.0 0.0" xyz="0.0 0.0 0.0"/>
      <geometry>
        <sphere radius="0.271"/>
      </geometry>
    </collision>
  </link>
  <gazebo reference="lower_body">
    <material>Gazebo/Grey</material>
  </gazebo>
  <link name="upper_body">
    <inertial>
      <origin rpy="0.0 0.0 0.0" xyz="0.0 0.0 0.55"/>
      <mass value="20.0"/>
      <inertia ixx="2.0886666666666667" ixy="0.0" ixz="0.0" iyy="2.0886666666666667" iyz="0.0" izz="0.144"/>
    </inertial>
    <collision>
      <origin rpy="0.0 0.0 0.0" xyz="0.0 0.0 0.55"/>
      <geometry>
        <cylinder length="1.1" radius="0.12"/>
      </geometry>
    </collision>
  </link>
  <gazebo reference="upper_body">
    <material>Gazebo/Grey</material>
  </gazebo>
  <link name="head">
    <inertial>
      <origin rpy="0.0 0.0 0.0" xyz="0.0 0.0 0.1"/>
      <mass value="0.01"/>
      <inertia ixx="0.00013333333333333337" ixy="0.0" ixz="0.0" iyy="0.00013333333333333337" iyz="0.0" izz="0.00020000000000000004"/>
    </inertial>
    <visual>
      <origin rpy="0.0 0.0 0.0" xyz="0.0 0.0 0.1"/>
      <geometry>
        <cylinder length="0.2" radius="0.2"/>
      </geometry>
      <material name="Black"/>
    </visual>
    <collision>
      <origin rpy="0.0 0.0 0.0" xyz="0.0 0.0 0.1"/>
      <geometry>
        <cylinder length="0.2" radius="0.2"/>
      </geometry>
    </collision>
  </link>
  <gazebo reference="head">
    <material>Gazebo/Black</material>
  </gazebo>
  <joint name="joint_base_link_body" type="fixed">
    <parent link="base_link"/>
    <child link="body"/>
    <origin rpy="0.0 0.0 0.0" xyz="0.0 0.0 0.0"/>
  </joint>
  <joint name="joint_body_mobile_base" type="fixed">
    <parent link="body"/>
    <child link="mobile_base"/>
    <origin rpy="0.0 0.0 0.0" xyz="0.0 0.0 0.0"/>
  </joint>
  <joint name="joint_body_lower_body" type="fixed">
    <parent link="body"/>
    <child link="lower_body"/>
    <origin rpy="0.0 0.0 0.0" xyz="0.0 0.0 0.5"/>
  </joint>
  <joint name="joint_body_upper_body" type="fixed">
    <parent link="body"/>
    <child link="upper_body"/>
    <origin rpy="0.0 0.0 0.0" xyz="0.0 0.0 0.5"/>
  </joint>
  <joint name="joint_body_head" type="fixed">
    <parent link="body"/>
    <child link="head"/>
    <origin rpy="0.0 0.0 0.0" xyz="0.0 0.0 1.3"/>
  </joint>
  <gazebo>
    <plugin filename="libgazebo_ros_planar_move.so" name="object_controller">
      <commandTopic>cmd_vel</commandTopic>
      <odometryTopic>odom</odometryTopic>
      <odometryFrame>odom</odometryFrame>
      <odometryRate>50.0</odometryRate>
      <robotBaseFrame>base_link</robotBaseFrame>
    </plugin>
  </gazebo>
  <gazebo reference="mobile_base">
    <mu1>0.001</mu1>
    <mu2>0.001</mu2>
  </gazebo>
  <!--
    Make sure the line below is <include>'d before this file.

    It's not <include>'d here to avoid re-including the same file multipe times.

    <xacro:include filename="$(find crosswing_ros)/urdf/domain.xacro"/>
  -->
  <!--
    Make sure the line below is <include>'d before this file.

    It's not <include>'d here to avoid re-including the same file multipe times.

    <xacro:include filename="$(find crosswing_ros)/urdf/domain.xacro"/>
  -->
  <!--
    Make sure the line below is <include>'d before this file.

    It's not <include>'d here to avoid re-including the same file multipe times.

    <xacro:include filename="$(find crosswing_ros)/urdf/domain.xacro"/>
  -->
  <!-- Reference frame for the virtual laser scan. -->
  <link name="laser"/>
  <joint name="joint_head_laser" type="fixed">
    <parent link="head"/>
    <child link="laser"/>
    <origin rpy="0.0 0.0 0.0" xyz="0.0 0.0 0.13"/>
  </joint>
  <link name="camera_front"/>
  <link name="camera_front_optical"/>
  <joint name="joint_head_camera_front" type="fixed">
    <parent link="head"/>
    <child link="camera_front"/>
    <origin rpy="0.0 0.0 0.0" xyz="0.2 0.0 0.13"/>
  </joint>
  <joint name="joint_camera_front_camera_front_optical" type="fixed">
    <parent link="camera_front"/>
    <child link="camera_front_optical"/>
    <origin rpy="-1.5707963267948966 0.0 -1.5707963267948966" xyz="0.0 0.0 0.0"/>
  </joint>
  <gazebo reference="camera_front">
    <sensor name="front_sensor_depth" type="depth">
      <update_rate>20</update_rate>
      <camera>
        <horizontal_fov>1.5009831567151235</horizontal_fov>
        <image>
          <width>640</width>
          <height>480</height>
          <format>R8G8B8</format>
        </image>
        <clip>
          <near>0.01</near>
          <far>40.0</far>
        </clip>
      </camera>
      <plugin filename="libgazebo_ros_openni_kinect.so" name="front_controller">
        <baseline>0.2</baseline>
        <alwaysOn>true</alwaysOn>
        <updateRate>20</updateRate>
        <cameraName>camera_front</cameraName>
        <imageTopicName>color/image_raw</imageTopicName>
        <cameraInfoTopicName>color/camera_info</cameraInfoTopicName>
        <depthImageTopicName>depth/image_raw</depthImageTopicName>
        <depthImageInfoTopicName>depth/camera_info</depthImageInfoTopicName>
        <pointCloudTopicName>depth/points</pointCloudTopicName>
        <frameName>camera_front_optical</frameName>
        <pointCloudCutoff>0.01</pointCloudCutoff>
        <pointCloudCutoffMax>40.0</pointCloudCutoffMax>
        <distortionK1>0.00000001</distortionK1>
        <distortionK2>0.00000001</distortionK2>
        <distortionK3>0.00000001</distortionK3>
        <distortionT1>0.00000001</distortionT1>
        <distortionT2>0.00000001</distortionT2>
        <CxPrime>0</CxPrime>
        <Cx>0</Cx>
        <Cy>0</Cy>
        <focalLength>0</focalLength>
        <hackBaseline>0</hackBaseline>
      </plugin>
    </sensor>
  </gazebo>
  <link name="camera_back"/>
  <link name="camera_back_optical"/>
  <joint name="joint_head_camera_back" type="fixed">
    <parent link="head"/>
    <child link="camera_back"/>
    <origin rpy="0.0 0.0 3.141592653589793" xyz="-0.2 0.0 0.13"/>
  </joint>
  <joint name="joint_camera_back_camera_back_optical" type="fixed">
    <parent link="camera_back"/>
    <child link="camera_back_optical"/>
    <origin rpy="-1.5707963267948966 0.0 -1.5707963267948966" xyz="0.0 0.0 0.0"/>
  </joint>
  <gazebo reference="camera_back">
    <sensor name="back_sensor_depth" type="depth">
      <update_rate>20</update_rate>
      <camera>
        <horizontal_fov>1.5009831567151235</horizontal_fov>
        <image>
          <width>640</width>
          <height>480</height>
          <format>R8G8B8</format>
        </image>
        <clip>
          <near>0.01</near>
          <far>40.0</far>
        </clip>
      </camera>
      <plugin filename="libgazebo_ros_openni_kinect.so" name="back_controller">
        <baseline>0.2</baseline>
        <alwaysOn>true</alwaysOn>
        <updateRate>20</updateRate>
        <cameraName>camera_back</cameraName>
        <imageTopicName>color/image_raw</imageTopicName>
        <cameraInfoTopicName>color/camera_info</cameraInfoTopicName>
        <depthImageTopicName>depth/image_raw</depthImageTopicName>
        <depthImageInfoTopicName>depth/camera_info</depthImageInfoTopicName>
        <pointCloudTopicName>depth/points</pointCloudTopicName>
        <frameName>camera_back_optical</frameName>
        <pointCloudCutoff>0.01</pointCloudCutoff>
        <pointCloudCutoffMax>40.0</pointCloudCutoffMax>
        <distortionK1>0.00000001</distortionK1>
        <distortionK2>0.00000001</distortionK2>
        <distortionK3>0.00000001</distortionK3>
        <distortionT1>0.00000001</distortionT1>
        <distortionT2>0.00000001</distortionT2>
        <CxPrime>0</CxPrime>
        <Cx>0</Cx>
        <Cy>0</Cy>
        <focalLength>0</focalLength>
        <hackBaseline>0</hackBaseline>
      </plugin>
    </sensor>
  </gazebo>
  <link name="camera_left"/>
  <link name="camera_left_optical"/>
  <joint name="joint_head_camera_left" type="fixed">
    <parent link="head"/>
    <child link="camera_left"/>
    <origin rpy="0.0 0.0 1.5707963267948966" xyz="0.0 0.2 0.13"/>
  </joint>
  <joint name="joint_camera_left_camera_left_optical" type="fixed">
    <parent link="camera_left"/>
    <child link="camera_left_optical"/>
    <origin rpy="-1.5707963267948966 0.0 -1.5707963267948966" xyz="0.0 0.0 0.0"/>
  </joint>
  <gazebo reference="camera_left">
    <sensor name="left_sensor_depth" type="depth">
      <update_rate>20</update_rate>
      <camera>
        <horizontal_fov>1.5009831567151235</horizontal_fov>
        <image>
          <width>640</width>
          <height>480</height>
          <format>R8G8B8</format>
        </image>
        <clip>
          <near>0.01</near>
          <far>40.0</far>
        </clip>
      </camera>
      <plugin filename="libgazebo_ros_openni_kinect.so" name="left_controller">
        <baseline>0.2</baseline>
        <alwaysOn>true</alwaysOn>
        <updateRate>20</updateRate>
        <cameraName>camera_left</cameraName>
        <imageTopicName>color/image_raw</imageTopicName>
        <cameraInfoTopicName>color/camera_info</cameraInfoTopicName>
        <depthImageTopicName>depth/image_raw</depthImageTopicName>
        <depthImageInfoTopicName>depth/camera_info</depthImageInfoTopicName>
        <pointCloudTopicName>depth/points</pointCloudTopicName>
        <frameName>camera_left_optical</frameName>
        <pointCloudCutoff>0.01</pointCloudCutoff>
        <pointCloudCutoffMax>40.0</pointCloudCutoffMax>
        <distortionK1>0.00000001</distortionK1>
        <distortionK2>0.00000001</distortionK2>
        <distortionK3>0.00000001</distortionK3>
        <distortionT1>0.00000001</distortionT1>
        <distortionT2>0.00000001</distortionT2>
        <CxPrime>0</CxPrime>
        <Cx>0</Cx>
        <Cy>0</Cy>
        <focalLength>0</focalLength>
        <hackBaseline>0</hackBaseline>
      </plugin>
    </sensor>
  </gazebo>
  <link name="camera_right"/>
  <link name="camera_right_optical"/>
  <joint name="joint_head_camera_right" type="fixed">
    <parent link="head"/>
    <child link="camera_right"/>
    <origin rpy="0.0 0.0 -1.5707963267948966" xyz="0.0 -0.2 0.13"/>
  </joint>
  <joint name="joint_camera_right_camera_right_optical" type="fixed">
    <parent link="camera_right"/>
    <child link="camera_right_optical"/>
    <origin rpy="-1.5707963267948966 0.0 -1.5707963267948966" xyz="0.0 0.0 0.0"/>
  </joint>
  <gazebo reference="camera_right">
    <sensor name="right_sensor_depth" type="depth">
      <update_rate>20</update_rate>
      <camera>
        <horizontal_fov>1.5009831567151235</horizontal_fov>
        <image>
          <width>640</width>
          <height>480</height>
          <format>R8G8B8</format>
        </image>
        <clip>
          <near>0.01</near>
          <far>40.0</far>
        </clip>
      </camera>
      <plugin filename="libgazebo_ros_openni_kinect.so" name="right_controller">
        <baseline>0.2</baseline>
        <alwaysOn>true</alwaysOn>
        <updateRate>20</updateRate>
        <cameraName>camera_right</cameraName>
        <imageTopicName>color/image_raw</imageTopicName>
        <cameraInfoTopicName>color/camera_info</cameraInfoTopicName>
        <depthImageTopicName>depth/image_raw</depthImageTopicName>
        <depthImageInfoTopicName>depth/camera_info</depthImageInfoTopicName>
        <pointCloudTopicName>depth/points</pointCloudTopicName>
        <frameName>camera_right_optical</frameName>
        <pointCloudCutoff>0.01</pointCloudCutoff>
        <pointCloudCutoffMax>40.0</pointCloudCutoffMax>
        <distortionK1>0.00000001</distortionK1>
        <distortionK2>0.00000001</distortionK2>
        <distortionK3>0.00000001</distortionK3>
        <distortionT1>0.00000001</distortionT1>
        <distortionT2>0.00000001</distortionT2>
        <CxPrime>0</CxPrime>
        <Cx>0</Cx>
        <Cy>0</Cy>
        <focalLength>0</focalLength>
        <hackBaseline>0</hackBaseline>
      </plugin>
    </sensor>
  </gazebo>
  <link name="tof_head_left_0"/>
  <joint name="joint_head_tof_head_left_0" type="fixed">
    <parent link="head"/>
    <child link="tof_head_left_0"/>
    <origin rpy="0.0 0.6239552075879728 0.2617993877991494" xyz="0.15454813220625094 0.04141104721640332 -0.04"/>
  </joint>
  <gazebo reference="tof_head_left_0">
    <sensor name="gazebo_ros_tof_head_left_0" type="ray">
      <pose>0 0 0 0 0 0</pose>
      <visualize>False</visualize>
      <update_rate>40</update_rate>
      <ray>
        <scan>
          <horizontal>
            <samples>1</samples>
            <resolution>1</resolution>
            <min_angle>0.0</min_angle>
            <max_angle>0.0</max_angle>
          </horizontal>
        </scan>
        <range>
          <min>0.01</min>
          <max>40.0</max>
          <resolution>0.01</resolution>
        </range>
        <noise>
          <type>gaussian</type>
          <mean>0.0</mean>
          <stddev>0.0</stddev>
        </noise>
      </ray>
      <plugin filename="libgazebo_ros_laser.so" name="gazebo_ros_tof_head_left_0_plugin">
        <topicName>scan/tof_head_left_0</topicName>
        <frameName>tof_head_left_0</frameName>
      </plugin>
    </sensor>
  </gazebo>
  <link name="tof_head_left_1"/>
  <joint name="joint_head_tof_head_left_1" type="fixed">
    <parent link="head"/>
    <child link="tof_head_left_1"/>
    <origin rpy="0.0 0.6239552075879728 0.7853981633974483" xyz="0.11313708498984762 0.11313708498984759 -0.04"/>
  </joint>
  <gazebo reference="tof_head_left_1">
    <sensor name="gazebo_ros_tof_head_left_1" type="ray">
      <pose>0 0 0 0 0 0</pose>
      <visualize>False</visualize>
      <update_rate>40</update_rate>
      <ray>
        <scan>
          <horizontal>
            <samples>1</samples>
            <resolution>1</resolution>
            <min_angle>0.0</min_angle>
            <max_angle>0.0</max_angle>
          </horizontal>
        </scan>
        <range>
          <min>0.01</min>
          <max>40.0</max>
          <resolution>0.01</resolution>
        </range>
        <noise>
          <type>gaussian</type>
          <mean>0.0</mean>
          <stddev>0.0</stddev>
        </noise>
      </ray>
      <plugin filename="libgazebo_ros_laser.so" name="gazebo_ros_tof_head_left_1_plugin">
        <topicName>scan/tof_head_left_1</topicName>
        <frameName>tof_head_left_1</frameName>
      </plugin>
    </sensor>
  </gazebo>
  <link name="tof_head_left_2"/>
  <joint name="joint_head_tof_head_left_2" type="fixed">
    <parent link="head"/>
    <child link="tof_head_left_2"/>
    <origin rpy="0.0 0.6239552075879728 1.308996938995747" xyz="0.04141104721640335 0.1545481322062509 -0.04"/>
  </joint>
  <gazebo reference="tof_head_left_2">
    <sensor name="gazebo_ros_tof_head_left_2" type="ray">
      <pose>0 0 0 0 0 0</pose>
      <visualize>False</visualize>
      <update_rate>40</update_rate>
      <ray>
        <scan>
          <horizontal>
            <samples>1</samples>
            <resolution>1</resolution>
            <min_angle>0.0</min_angle>
            <max_angle>0.0</max_angle>
          </horizontal>
        </scan>
        <range>
          <min>0.01</min>
          <max>40.0</max>
          <resolution>0.01</resolution>
        </range>
        <noise>
          <type>gaussian</type>
          <mean>0.0</mean>
          <stddev>0.0</stddev>
        </noise>
      </ray>
      <plugin filename="libgazebo_ros_laser.so" name="gazebo_ros_tof_head_left_2_plugin">
        <topicName>scan/tof_head_left_2</topicName>
        <frameName>tof_head_left_2</frameName>
      </plugin>
    </sensor>
  </gazebo>
  <link name="tof_head_left_3"/>
  <joint name="joint_head_tof_head_left_3" type="fixed">
    <parent link="head"/>
    <child link="tof_head_left_3"/>
    <origin rpy="0.0 0.6239552075879728 1.832595714594046" xyz="-0.041411047216403304 0.15454813220625094 -0.04"/>
  </joint>
  <gazebo reference="tof_head_left_3">
    <sensor name="gazebo_ros_tof_head_left_3" type="ray">
      <pose>0 0 0 0 0 0</pose>
      <visualize>False</visualize>
      <update_rate>40</update_rate>
      <ray>
        <scan>
          <horizontal>
            <samples>1</samples>
            <resolution>1</resolution>
            <min_angle>0.0</min_angle>
            <max_angle>0.0</max_angle>
          </horizontal>
        </scan>
        <range>
          <min>0.01</min>
          <max>40.0</max>
          <resolution>0.01</resolution>
        </range>
        <noise>
          <type>gaussian</type>
          <mean>0.0</mean>
          <stddev>0.0</stddev>
        </noise>
      </ray>
      <plugin filename="libgazebo_ros_laser.so" name="gazebo_ros_tof_head_left_3_plugin">
        <topicName>scan/tof_head_left_3</topicName>
        <frameName>tof_head_left_3</frameName>
      </plugin>
    </sensor>
  </gazebo>
  <link name="tof_head_left_4"/>
  <joint name="joint_head_tof_head_left_4" type="fixed">
    <parent link="head"/>
    <child link="tof_head_left_4"/>
    <origin rpy="0.0 0.6239552075879728 2.356194490192345" xyz="-0.11313708498984759 0.11313708498984762 -0.04"/>
  </joint>
  <gazebo reference="tof_head_left_4">
    <sensor name="gazebo_ros_tof_head_left_4" type="ray">
      <pose>0 0 0 0 0 0</pose>
      <visualize>False</visualize>
      <update_rate>40</update_rate>
      <ray>
        <scan>
          <horizontal>
            <samples>1</samples>
            <resolution>1</resolution>
            <min_angle>0.0</min_angle>
            <max_angle>0.0</max_angle>
          </horizontal>
        </scan>
        <range>
          <min>0.01</min>
          <max>40.0</max>
          <resolution>0.01</resolution>
        </range>
        <noise>
          <type>gaussian</type>
          <mean>0.0</mean>
          <stddev>0.0</stddev>
        </noise>
      </ray>
      <plugin filename="libgazebo_ros_laser.so" name="gazebo_ros_tof_head_left_4_plugin">
        <topicName>scan/tof_head_left_4</topicName>
        <frameName>tof_head_left_4</frameName>
      </plugin>
    </sensor>
  </gazebo>
  <link name="tof_head_left_5"/>
  <joint name="joint_head_tof_head_left_5" type="fixed">
    <parent link="head"/>
    <child link="tof_head_left_5"/>
    <origin rpy="0.0 0.6239552075879728 2.8797932657906435" xyz="-0.1545481322062509 0.04141104721640337 -0.04"/>
  </joint>
  <gazebo reference="tof_head_left_5">
    <sensor name="gazebo_ros_tof_head_left_5" type="ray">
      <pose>0 0 0 0 0 0</pose>
      <visualize>False</visualize>
      <update_rate>40</update_rate>
      <ray>
        <scan>
          <horizontal>
            <samples>1</samples>
            <resolution>1</resolution>
            <min_angle>0.0</min_angle>
            <max_angle>0.0</max_angle>
          </horizontal>
        </scan>
        <range>
          <min>0.01</min>
          <max>40.0</max>
          <resolution>0.01</resolution>
        </range>
        <noise>
          <type>gaussian</type>
          <mean>0.0</mean>
          <stddev>0.0</stddev>
        </noise>
      </ray>
      <plugin filename="libgazebo_ros_laser.so" name="gazebo_ros_tof_head_left_5_plugin">
        <topicName>scan/tof_head_left_5</topicName>
        <frameName>tof_head_left_5</frameName>
      </plugin>
    </sensor>
  </gazebo>
  <link name="tof_head_right_0"/>
  <joint name="joint_head_tof_head_right_0" type="fixed">
    <parent link="head"/>
    <child link="tof_head_right_0"/>
    <origin rpy="0.0 0.6239552075879728 -0.2617993877991494" xyz="0.15454813220625094 -0.04141104721640332 -0.04"/>
  </joint>
  <gazebo reference="tof_head_right_0">
    <sensor name="gazebo_ros_tof_head_right_0" type="ray">
      <pose>0 0 0 0 0 0</pose>
      <visualize>False</visualize>
      <update_rate>40</update_rate>
      <ray>
        <scan>
          <horizontal>
            <samples>1</samples>
            <resolution>1</resolution>
            <min_angle>0.0</min_angle>
            <max_angle>0.0</max_angle>
          </horizontal>
        </scan>
        <range>
          <min>0.01</min>
          <max>40.0</max>
          <resolution>0.01</resolution>
        </range>
        <noise>
          <type>gaussian</type>
          <mean>0.0</mean>
          <stddev>0.0</stddev>
        </noise>
      </ray>
      <plugin filename="libgazebo_ros_laser.so" name="gazebo_ros_tof_head_right_0_plugin">
        <topicName>scan/tof_head_right_0</topicName>
        <frameName>tof_head_right_0</frameName>
      </plugin>
    </sensor>
  </gazebo>
  <link name="tof_head_right_1"/>
  <joint name="joint_head_tof_head_right_1" type="fixed">
    <parent link="head"/>
    <child link="tof_head_right_1"/>
    <origin rpy="0.0 0.6239552075879728 -0.7853981633974483" xyz="0.11313708498984762 -0.11313708498984759 -0.04"/>
  </joint>
  <gazebo reference="tof_head_right_1">
    <sensor name="gazebo_ros_tof_head_right_1" type="ray">
      <pose>0 0 0 0 0 0</pose>
      <visualize>False</visualize>
      <update_rate>40</update_rate>
      <ray>
        <scan>
          <horizontal>
            <samples>1</samples>
            <resolution>1</resolution>
            <min_angle>0.0</min_angle>
            <max_angle>0.0</max_angle>
          </horizontal>
        </scan>
        <range>
          <min>0.01</min>
          <max>40.0</max>
          <resolution>0.01</resolution>
        </range>
        <noise>
          <type>gaussian</type>
          <mean>0.0</mean>
          <stddev>0.0</stddev>
        </noise>
      </ray>
      <plugin filename="libgazebo_ros_laser.so" name="gazebo_ros_tof_head_right_1_plugin">
        <topicName>scan/tof_head_right_1</topicName>
        <frameName>tof_head_right_1</frameName>
      </plugin>
    </sensor>
  </gazebo>
  <link name="tof_head_right_2"/>
  <joint name="joint_head_tof_head_right_2" type="fixed">
    <parent link="head"/>
    <child link="tof_head_right_2"/>
    <origin rpy="0.0 0.6239552075879728 -1.308996938995747" xyz="0.04141104721640335 -0.1545481322062509 -0.04"/>
  </joint>
  <gazebo reference="tof_head_right_2">
    <sensor name="gazebo_ros_tof_head_right_2" type="ray">
      <pose>0 0 0 0 0 0</pose>
      <visualize>False</visualize>
      <update_rate>40</update_rate>
      <ray>
        <scan>
          <horizontal>
            <samples>1</samples>
            <resolution>1</resolution>
            <min_angle>0.0</min_angle>
            <max_angle>0.0</max_angle>
          </horizontal>
        </scan>
        <range>
          <min>0.01</min>
          <max>40.0</max>
          <resolution>0.01</resolution>
        </range>
        <noise>
          <type>gaussian</type>
          <mean>0.0</mean>
          <stddev>0.0</stddev>
        </noise>
      </ray>
      <plugin filename="libgazebo_ros_laser.so" name="gazebo_ros_tof_head_right_2_plugin">
        <topicName>scan/tof_head_right_2</topicName>
        <frameName>tof_head_right_2</frameName>
      </plugin>
    </sensor>
  </gazebo>
  <link name="tof_head_right_3"/>
  <joint name="joint_head_tof_head_right_3" type="fixed">
    <parent link="head"/>
    <child link="tof_head_right_3"/>
    <origin rpy="0.0 0.6239552075879728 -1.832595714594046" xyz="-0.041411047216403304 -0.15454813220625094 -0.04"/>
  </joint>
  <gazebo reference="tof_head_right_3">
    <sensor name="gazebo_ros_tof_head_right_3" type="ray">
      <pose>0 0 0 0 0 0</pose>
      <visualize>False</visualize>
      <update_rate>40</update_rate>
      <ray>
        <scan>
          <horizontal>
            <samples>1</samples>
            <resolution>1</resolution>
            <min_angle>0.0</min_angle>
            <max_angle>0.0</max_angle>
          </horizontal>
        </scan>
        <range>
          <min>0.01</min>
          <max>40.0</max>
          <resolution>0.01</resolution>
        </range>
        <noise>
          <type>gaussian</type>
          <mean>0.0</mean>
          <stddev>0.0</stddev>
        </noise>
      </ray>
      <plugin filename="libgazebo_ros_laser.so" name="gazebo_ros_tof_head_right_3_plugin">
        <topicName>scan/tof_head_right_3</topicName>
        <frameName>tof_head_right_3</frameName>
      </plugin>
    </sensor>
  </gazebo>
  <link name="tof_head_right_4"/>
  <joint name="joint_head_tof_head_right_4" type="fixed">
    <parent link="head"/>
    <child link="tof_head_right_4"/>
    <origin rpy="0.0 0.6239552075879728 -2.356194490192345" xyz="-0.11313708498984759 -0.11313708498984762 -0.04"/>
  </joint>
  <gazebo reference="tof_head_right_4">
    <sensor name="gazebo_ros_tof_head_right_4" type="ray">
      <pose>0 0 0 0 0 0</pose>
      <visualize>False</visualize>
      <update_rate>40</update_rate>
      <ray>
        <scan>
          <horizontal>
            <samples>1</samples>
            <resolution>1</resolution>
            <min_angle>0.0</min_angle>
            <max_angle>0.0</max_angle>
          </horizontal>
        </scan>
        <range>
          <min>0.01</min>
          <max>40.0</max>
          <resolution>0.01</resolution>
        </range>
        <noise>
          <type>gaussian</type>
          <mean>0.0</mean>
          <stddev>0.0</stddev>
        </noise>
      </ray>
      <plugin filename="libgazebo_ros_laser.so" name="gazebo_ros_tof_head_right_4_plugin">
        <topicName>scan/tof_head_right_4</topicName>
        <frameName>tof_head_right_4</frameName>
      </plugin>
    </sensor>
  </gazebo>
  <link name="tof_head_right_5"/>
  <joint name="joint_head_tof_head_right_5" type="fixed">
    <parent link="head"/>
    <child link="tof_head_right_5"/>
    <origin rpy="0.0 0.6239552075879728 -2.8797932657906435" xyz="-0.1545481322062509 -0.04141104721640337 -0.04"/>
  </joint>
  <gazebo reference="tof_head_right_5">
    <sensor name="gazebo_ros_tof_head_right_5" type="ray">
      <pose>0 0 0 0 0 0</pose>
      <visualize>False</visualize>
      <update_rate>40</update_rate>
      <ray>
        <scan>
          <horizontal>
            <samples>1</samples>
            <resolution>1</resolution>
            <min_angle>0.0</min_angle>
            <max_angle>0.0</max_angle>
          </horizontal>
        </scan>
        <range>
          <min>0.01</min>
          <max>40.0</max>
          <resolution>0.01</resolution>
        </range>
        <noise>
          <type>gaussian</type>
          <mean>0.0</mean>
          <stddev>0.0</stddev>
        </noise>
      </ray>
      <plugin filename="libgazebo_ros_laser.so" name="gazebo_ros_tof_head_right_5_plugin">
        <topicName>scan/tof_head_right_5</topicName>
        <frameName>tof_head_right_5</frameName>
      </plugin>
    </sensor>
  </gazebo>
  <!-- Converted from 62.46d to the reference frame between thrusters. -->
  <link name="tof_base_front"/>
  <joint name="joint_body_tof_base_front" type="fixed">
    <parent link="body"/>
    <child link="tof_base_front"/>
    <origin rpy="0.0 0.0 0.0" xyz="0.0 0.0 0.36"/>
  </joint>
  <link name="tof_base_front_left"/>
  <joint name="joint_tof_base_front_tof_base_front_left" type="fixed">
    <parent link="tof_base_front"/>
    <child link="tof_base_front_left"/>
    <origin rpy="0.0 0.4637339822548934 -1.0042624515975371" xyz="0.16400000000000003 0.28405633244129586 0.04"/>
  </joint>
  <gazebo reference="tof_base_front_left">
    <sensor name="gazebo_ros_tof_base_front_left" type="ray">
      <pose>0 0 0 0 0 0</pose>
      <visualize>False</visualize>
      <update_rate>40</update_rate>
      <ray>
        <scan>
          <horizontal>
            <samples>1</samples>
            <resolution>1</resolution>
            <min_angle>0.0</min_angle>
            <max_angle>0.0</max_angle>
          </horizontal>
        </scan>
        <range>
          <min>0.05</min>
          <max>40.0</max>
          <resolution>0.01</resolution>
        </range>
        <noise>
          <type>gaussian</type>
          <mean>0.0</mean>
          <stddev>0.0</stddev>
        </noise>
      </ray>
      <plugin filename="libgazebo_ros_laser.so" name="gazebo_ros_tof_base_front_left_plugin">
        <topicName>scan/tof_base_front_left</topicName>
        <frameName>tof_base_front_left</frameName>
      </plugin>
    </sensor>
  </gazebo>
  <link name="tof_base_front_center"/>
  <joint name="joint_tof_base_front_tof_base_front_center" type="fixed">
    <parent link="tof_base_front"/>
    <child link="tof_base_front_center"/>
    <origin rpy="0.0 0.4637339822548934 0.0" xyz="0.271 0.0 0.0"/>
  </joint>
  <gazebo reference="tof_base_front_center">
    <sensor name="gazebo_ros_tof_base_front_center" type="ray">
      <pose>0 0 0 0 0 0</pose>
      <visualize>False</visualize>
      <update_rate>40</update_rate>
      <ray>
        <scan>
          <horizontal>
            <samples>1</samples>
            <resolution>1</resolution>
            <min_angle>0.0</min_angle>
            <max_angle>0.0</max_angle>
          </horizontal>
        </scan>
        <range>
          <min>0.01</min>
          <max>40.0</max>
          <resolution>0.01</resolution>
        </range>
        <noise>
          <type>gaussian</type>
          <mean>0.0</mean>
          <stddev>0.0</stddev>
        </noise>
      </ray>
      <plugin filename="libgazebo_ros_laser.so" name="gazebo_ros_tof_base_front_center_plugin">
        <topicName>scan/tof_base_front_center</topicName>
        <frameName>tof_base_front_center</frameName>
      </plugin>
    </sensor>
  </gazebo>
  <link name="tof_base_front_right"/>
  <joint name="joint_tof_base_front_tof_base_front_right" type="fixed">
    <parent link="tof_base_front"/>
    <child link="tof_base_front_right"/>
    <origin rpy="0.0 0.4637339822548934 1.0042624515975371" xyz="0.16400000000000003 -0.28405633244129586 0.04"/>
  </joint>
  <gazebo reference="tof_base_front_right">
    <sensor name="gazebo_ros_tof_base_front_right" type="ray">
      <pose>0 0 0 0 0 0</pose>
      <visualize>False</visualize>
      <update_rate>40</update_rate>
      <ray>
        <scan>
          <horizontal>
            <samples>1</samples>
            <resolution>1</resolution>
            <min_angle>0.0</min_angle>
            <max_angle>0.0</max_angle>
          </horizontal>
        </scan>
        <range>
          <min>0.05</min>
          <max>40.0</max>
          <resolution>0.01</resolution>
        </range>
        <noise>
          <type>gaussian</type>
          <mean>0.0</mean>
          <stddev>0.0</stddev>
        </noise>
      </ray>
      <plugin filename="libgazebo_ros_laser.so" name="gazebo_ros_tof_base_front_right_plugin">
        <topicName>scan/tof_base_front_right</topicName>
        <frameName>tof_base_front_right</frameName>
      </plugin>
    </sensor>
  </gazebo>
  <link name="tof_base_left"/>
  <joint name="joint_body_tof_base_left" type="fixed">
    <parent link="body"/>
    <child link="tof_base_left"/>
    <origin rpy="0.0 0.0 2.0943951023931953" xyz="0.0 0.0 0.36"/>
  </joint>
  <link name="tof_base_left_left"/>
  <joint name="joint_tof_base_left_tof_base_left_left" type="fixed">
    <parent link="tof_base_left"/>
    <child link="tof_base_left_left"/>
    <origin rpy="0.0 0.4637339822548934 -1.0042624515975371" xyz="0.16400000000000003 0.28405633244129586 0.04"/>
  </joint>
  <gazebo reference="tof_base_left_left">
    <sensor name="gazebo_ros_tof_base_left_left" type="ray">
      <pose>0 0 0 0 0 0</pose>
      <visualize>False</visualize>
      <update_rate>40</update_rate>
      <ray>
        <scan>
          <horizontal>
            <samples>1</samples>
            <resolution>1</resolution>
            <min_angle>0.0</min_angle>
            <max_angle>0.0</max_angle>
          </horizontal>
        </scan>
        <range>
          <min>0.05</min>
          <max>40.0</max>
          <resolution>0.01</resolution>
        </range>
        <noise>
          <type>gaussian</type>
          <mean>0.0</mean>
          <stddev>0.0</stddev>
        </noise>
      </ray>
      <plugin filename="libgazebo_ros_laser.so" name="gazebo_ros_tof_base_left_left_plugin">
        <topicName>scan/tof_base_left_left</topicName>
        <frameName>tof_base_left_left</frameName>
      </plugin>
    </sensor>
  </gazebo>
  <link name="tof_base_left_center"/>
  <joint name="joint_tof_base_left_tof_base_left_center" type="fixed">
    <parent link="tof_base_left"/>
    <child link="tof_base_left_center"/>
    <origin rpy="0.0 0.4637339822548934 0.0" xyz="0.271 0.0 0.0"/>
  </joint>
  <gazebo reference="tof_base_left_center">
    <sensor name="gazebo_ros_tof_base_left_center" type="ray">
      <pose>0 0 0 0 0 0</pose>
      <visualize>False</visualize>
      <update_rate>40</update_rate>
      <ray>
        <scan>
          <horizontal>
            <samples>1</samples>
            <resolution>1</resolution>
            <min_angle>0.0</min_angle>
            <max_angle>0.0</max_angle>
          </horizontal>
        </scan>
        <range>
          <min>0.01</min>
          <max>40.0</max>
          <resolution>0.01</resolution>
        </range>
        <noise>
          <type>gaussian</type>
          <mean>0.0</mean>
          <stddev>0.0</stddev>
        </noise>
      </ray>
      <plugin filename="libgazebo_ros_laser.so" name="gazebo_ros_tof_base_left_center_plugin">
        <topicName>scan/tof_base_left_center</topicName>
        <frameName>tof_base_left_center</frameName>
      </plugin>
    </sensor>
  </gazebo>
  <link name="tof_base_left_right"/>
  <joint name="joint_tof_base_left_tof_base_left_right" type="fixed">
    <parent link="tof_base_left"/>
    <child link="tof_base_left_right"/>
    <origin rpy="0.0 0.4637339822548934 1.0042624515975371" xyz="0.16400000000000003 -0.28405633244129586 0.04"/>
  </joint>
  <gazebo reference="tof_base_left_right">
    <sensor name="gazebo_ros_tof_base_left_right" type="ray">
      <pose>0 0 0 0 0 0</pose>
      <visualize>False</visualize>
      <update_rate>40</update_rate>
      <ray>
        <scan>
          <horizontal>
            <samples>1</samples>
            <resolution>1</resolution>
            <min_angle>0.0</min_angle>
            <max_angle>0.0</max_angle>
          </horizontal>
        </scan>
        <range>
          <min>0.05</min>
          <max>40.0</max>
          <resolution>0.01</resolution>
        </range>
        <noise>
          <type>gaussian</type>
          <mean>0.0</mean>
          <stddev>0.0</stddev>
        </noise>
      </ray>
      <plugin filename="libgazebo_ros_laser.so" name="gazebo_ros_tof_base_left_right_plugin">
        <topicName>scan/tof_base_left_right</topicName>
        <frameName>tof_base_left_right</frameName>
      </plugin>
    </sensor>
  </gazebo>
  <link name="tof_base_right"/>
  <joint name="joint_body_tof_base_right" type="fixed">
    <parent link="body"/>
    <child link="tof_base_right"/>
    <origin rpy="0.0 0.0 -2.0943951023931953" xyz="0.0 0.0 0.36"/>
  </joint>
  <link name="tof_base_right_left"/>
  <joint name="joint_tof_base_right_tof_base_right_left" type="fixed">
    <parent link="tof_base_right"/>
    <child link="tof_base_right_left"/>
    <origin rpy="0.0 0.4637339822548934 -1.0042624515975371" xyz="0.16400000000000003 0.28405633244129586 0.04"/>
  </joint>
  <gazebo reference="tof_base_right_left">
    <sensor name="gazebo_ros_tof_base_right_left" type="ray">
      <pose>0 0 0 0 0 0</pose>
      <visualize>False</visualize>
      <update_rate>40</update_rate>
      <ray>
        <scan>
          <horizontal>
            <samples>1</samples>
            <resolution>1</resolution>
            <min_angle>0.0</min_angle>
            <max_angle>0.0</max_angle>
          </horizontal>
        </scan>
        <range>
          <min>0.05</min>
          <max>40.0</max>
          <resolution>0.01</resolution>
        </range>
        <noise>
          <type>gaussian</type>
          <mean>0.0</mean>
          <stddev>0.0</stddev>
        </noise>
      </ray>
      <plugin filename="libgazebo_ros_laser.so" name="gazebo_ros_tof_base_right_left_plugin">
        <topicName>scan/tof_base_right_left</topicName>
        <frameName>tof_base_right_left</frameName>
      </plugin>
    </sensor>
  </gazebo>
  <link name="tof_base_right_center"/>
  <joint name="joint_tof_base_right_tof_base_right_center" type="fixed">
    <parent link="tof_base_right"/>
    <child link="tof_base_right_center"/>
    <origin rpy="0.0 0.4637339822548934 0.0" xyz="0.271 0.0 0.0"/>
  </joint>
  <gazebo reference="tof_base_right_center">
    <sensor name="gazebo_ros_tof_base_right_center" type="ray">
      <pose>0 0 0 0 0 0</pose>
      <visualize>False</visualize>
      <update_rate>40</update_rate>
      <ray>
        <scan>
          <horizontal>
            <samples>1</samples>
            <resolution>1</resolution>
            <min_angle>0.0</min_angle>
            <max_angle>0.0</max_angle>
          </horizontal>
        </scan>
        <range>
          <min>0.01</min>
          <max>40.0</max>
          <resolution>0.01</resolution>
        </range>
        <noise>
          <type>gaussian</type>
          <mean>0.0</mean>
          <stddev>0.0</stddev>
        </noise>
      </ray>
      <plugin filename="libgazebo_ros_laser.so" name="gazebo_ros_tof_base_right_center_plugin">
        <topicName>scan/tof_base_right_center</topicName>
        <frameName>tof_base_right_center</frameName>
      </plugin>
    </sensor>
  </gazebo>
  <link name="tof_base_right_right"/>
  <joint name="joint_tof_base_right_tof_base_right_right" type="fixed">
    <parent link="tof_base_right"/>
    <child link="tof_base_right_right"/>
    <origin rpy="0.0 0.4637339822548934 1.0042624515975371" xyz="0.16400000000000003 -0.28405633244129586 0.04"/>
  </joint>
  <gazebo reference="tof_base_right_right">
    <sensor name="gazebo_ros_tof_base_right_right" type="ray">
      <pose>0 0 0 0 0 0</pose>
      <visualize>False</visualize>
      <update_rate>40</update_rate>
      <ray>
        <scan>
          <horizontal>
            <samples>1</samples>
            <resolution>1</resolution>
            <min_angle>0.0</min_angle>
            <max_angle>0.0</max_angle>
          </horizontal>
        </scan>
        <range>
          <min>0.05</min>
          <max>40.0</max>
          <resolution>0.01</resolution>
        </range>
        <noise>
          <type>gaussian</type>
          <mean>0.0</mean>
          <stddev>0.0</stddev>
        </noise>
      </ray>
      <plugin filename="libgazebo_ros_laser.so" name="gazebo_ros_tof_base_right_right_plugin">
        <topicName>scan/tof_base_right_right</topicName>
        <frameName>tof_base_right_right</frameName>
      </plugin>
    </sensor>
  </gazebo>
  <!--
    Make sure the line below is <include>'d before this file.

    It's not <include>'d here to avoid re-including the same file multipe times.

    <xacro:include filename="$(find crosswing_ros)/urdf/domain.xacro"/>
  -->
  <link name="light_left_height">
    <inertial>
      <origin rpy="0.0 1.5707963267948966 0.0" xyz="-0.085 0.0 0.0"/>
      <mass value="0.09424777960769382"/>
      <inertia ixx="0.00046711555768063246" ixy="0.0" ixz="0.0" iyy="0.00046711555768063246" iyz="0.0" izz="2.9452431127404324e-05"/>
    </inertial>
    <visual>
      <origin rpy="0.0 1.5707963267948966 0.0" xyz="-0.085 0.0 0.0"/>
      <geometry>
        <cylinder length="0.24" radius="0.025"/>
      </geometry>
      <material name="Black"/>
    </visual>
    <collision>
      <origin rpy="0.0 1.5707963267948966 0.0" xyz="-0.085 0.0 0.0"/>
      <geometry>
        <cylinder length="0.24" radius="0.025"/>
      </geometry>
    </collision>
  </link>
  <gazebo reference="light_left_height">
    <material>Gazebo/Black</material>
  </gazebo>
  <link name="light_left_roll">
    <inertial>
      <origin rpy="0.0 0.0 0.0" xyz="0.0 0.0 0.0"/>
      <mass value="0.5222897786593033"/>
      <inertia ixx="0.00013057244466482584" ixy="0.0" ixz="0.0" iyy="0.00013057244466482584" iyz="0.0" izz="0.00013057244466482584"/>
    </inertial>
    <visual>
      <origin rpy="0.0 0.0 0.0" xyz="0.0 0.0 0.0"/>
      <geometry>
        <sphere radius="0.025"/>
      </geometry>
      <material name="Black"/>
    </visual>
    <collision>
      <origin rpy="0.0 0.0 0.0" xyz="0.0 0.0 0.0"/>
      <geometry>
        <sphere radius="0.025"/>
      </geometry>
    </collision>
  </link>
  <gazebo reference="light_left_roll">
    <material>Gazebo/Black</material>
  </gazebo>
  <link name="light_left">
    <inertial>
      <origin rpy="0.0 0.0 0.0" xyz="0.125 0.0 0.0"/>
      <mass value="0.8"/>
      <inertia ixx="0.010833333333333335" ixy="0.0" ixz="0.0" iyy="0.002833333333333334" iyz="0.0" izz="0.013333333333333336"/>
    </inertial>
    <visual>
      <origin rpy="0.0 0.0 0.0" xyz="0.125 0.0 0.0"/>
      <geometry>
        <box size="0.2 0.4 0.05"/>
      </geometry>
      <material name="Black"/>
    </visual>
    <collision>
      <origin rpy="0.0 0.0 0.0" xyz="0.125 0.0 0.0"/>
      <geometry>
        <box size="0.2 0.4 0.05"/>
      </geometry>
    </collision>
  </link>
  <gazebo reference="light_left">
    <material>Gazebo/Black</material>
  </gazebo>
  <link name="light_left_light">
    <inertial>
      <origin rpy="0.0 0.0 0.0" xyz="0.125 0.0 0.016"/>
      <mass value="0.2736"/>
      <inertia ixx="0.0033014400000000005" ixy="0.0" ixz="0.0" iyy="0.0007478399999999999" iyz="0.0" izz="0.0040310400000000005"/>
    </inertial>
    <visual>
      <origin rpy="0.0 0.0 0.0" xyz="0.125 0.0 0.016"/>
      <geometry>
        <box size="0.18 0.38 0.02"/>
      </geometry>
      <material name="White"/>
    </visual>
    <collision>
      <origin rpy="0.0 0.0 0.0" xyz="0.125 0.0 0.016"/>
      <geometry>
        <box size="0.18 0.38 0.02"/>
      </geometry>
    </collision>
  </link>
  <gazebo reference="light_left_light">
    <material>Gazebo/White</material>
  </gazebo>
  <joint name="joint_light_left_height" type="prismatic">
    <parent link="mobile_base"/>
    <child link="light_left_height"/>
    <origin rpy="0.0 0.0 1.0471975511965976" xyz="0.16500000000000004 0.28578838324886474 0.25"/>
    <axis xyz="0 0 1"/>
    <limit effort="100.0" lower="-0.18" upper="0.15" velocity="1.0"/>
  </joint>
  <transmission name="light_left_height_transmission">
    <type>transmission_interface/SimpleTransmission</type>
    <joint name="joint_light_left_height">
      <hardwareInterface>hardware_interface/EffortJointInterface</hardwareInterface>
    </joint>
    <actuator name="light_left_height_actuator">
      <mechanicalReduction>1</mechanicalReduction>
    </actuator>
  </transmission>
  <joint name="joint_light_left_roll" type="revolute">
    <parent link="light_left_height"/>
    <child link="light_left_roll"/>
    <origin rpy="0.0 0.0 0.0" xyz="0.035 0.0 0.0"/>
    <axis xyz="1 0 0"/>
    <limit effort="20.0" lower="-3.141592653589793" upper="3.141592653589793" velocity="1.0"/>
  </joint>
  <transmission name="light_left_roll_transmission">
    <type>transmission_interface/SimpleTransmission</type>
    <joint name="joint_light_left_roll">
      <hardwareInterface>hardware_interface/EffortJointInterface</hardwareInterface>
    </joint>
    <actuator name="light_left_roll_actuator">
      <mechanicalReduction>1</mechanicalReduction>
    </actuator>
  </transmission>
  <joint name="joint_light_left_pitch" type="revolute">
    <parent link="light_left_roll"/>
    <child link="light_left"/>
    <origin rpy="0.0 0.0 0.0" xyz="0.0 0.0 0.0"/>
    <axis xyz="0 1 0"/>
    <limit effort="20.0" lower="-1.5707963267948966" upper="1.5707963267948966" velocity="1.0"/>
  </joint>
  <transmission name="light_left_pitch_transmission">
    <type>transmission_interface/SimpleTransmission</type>
    <joint name="joint_light_left_pitch">
      <hardwareInterface>hardware_interface/EffortJointInterface</hardwareInterface>
    </joint>
    <actuator name="light_left_pitch_actuator">
      <mechanicalReduction>1</mechanicalReduction>
    </actuator>
  </transmission>
  <joint name="joint_light_left_light_left_light" type="fixed">
    <parent link="light_left"/>
    <child link="light_left_light"/>
    <origin rpy="0.0 0.0 0.0" xyz="0.0 0.0 0.0"/>
  </joint>
  <gazebo reference="joint_light_left_light_left_light">
    <preserveFixedJoint>true</preserveFixedJoint>
  </gazebo>
  <link name="light_back_height">
    <inertial>
      <origin rpy="0.0 1.5707963267948966 0.0" xyz="-0.085 0.0 0.0"/>
      <mass value="0.09424777960769382"/>
      <inertia ixx="0.00046711555768063246" ixy="0.0" ixz="0.0" iyy="0.00046711555768063246" iyz="0.0" izz="2.9452431127404324e-05"/>
    </inertial>
    <visual>
      <origin rpy="0.0 1.5707963267948966 0.0" xyz="-0.085 0.0 0.0"/>
      <geometry>
        <cylinder length="0.24" radius="0.025"/>
      </geometry>
      <material name="Black"/>
    </visual>
    <collision>
      <origin rpy="0.0 1.5707963267948966 0.0" xyz="-0.085 0.0 0.0"/>
      <geometry>
        <cylinder length="0.24" radius="0.025"/>
      </geometry>
    </collision>
  </link>
  <gazebo reference="light_back_height">
    <material>Gazebo/Black</material>
  </gazebo>
  <link name="light_back_roll">
    <inertial>
      <origin rpy="0.0 0.0 0.0" xyz="0.0 0.0 0.0"/>
      <mass value="0.5222897786593033"/>
      <inertia ixx="0.00013057244466482584" ixy="0.0" ixz="0.0" iyy="0.00013057244466482584" iyz="0.0" izz="0.00013057244466482584"/>
    </inertial>
    <visual>
      <origin rpy="0.0 0.0 0.0" xyz="0.0 0.0 0.0"/>
      <geometry>
        <sphere radius="0.025"/>
      </geometry>
      <material name="Black"/>
    </visual>
    <collision>
      <origin rpy="0.0 0.0 0.0" xyz="0.0 0.0 0.0"/>
      <geometry>
        <sphere radius="0.025"/>
      </geometry>
    </collision>
  </link>
  <gazebo reference="light_back_roll">
    <material>Gazebo/Black</material>
  </gazebo>
  <link name="light_back">
    <inertial>
      <origin rpy="0.0 0.0 0.0" xyz="0.125 0.0 0.0"/>
      <mass value="0.8"/>
      <inertia ixx="0.010833333333333335" ixy="0.0" ixz="0.0" iyy="0.002833333333333334" iyz="0.0" izz="0.013333333333333336"/>
    </inertial>
    <visual>
      <origin rpy="0.0 0.0 0.0" xyz="0.125 0.0 0.0"/>
      <geometry>
        <box size="0.2 0.4 0.05"/>
      </geometry>
      <material name="Black"/>
    </visual>
    <collision>
      <origin rpy="0.0 0.0 0.0" xyz="0.125 0.0 0.0"/>
      <geometry>
        <box size="0.2 0.4 0.05"/>
      </geometry>
    </collision>
  </link>
  <gazebo reference="light_back">
    <material>Gazebo/Black</material>
  </gazebo>
  <link name="light_back_light">
    <inertial>
      <origin rpy="0.0 0.0 0.0" xyz="0.125 0.0 0.016"/>
      <mass value="0.2736"/>
      <inertia ixx="0.0033014400000000005" ixy="0.0" ixz="0.0" iyy="0.0007478399999999999" iyz="0.0" izz="0.0040310400000000005"/>
    </inertial>
    <visual>
      <origin rpy="0.0 0.0 0.0" xyz="0.125 0.0 0.016"/>
      <geometry>
        <box size="0.18 0.38 0.02"/>
      </geometry>
      <material name="White"/>
    </visual>
    <collision>
      <origin rpy="0.0 0.0 0.0" xyz="0.125 0.0 0.016"/>
      <geometry>
        <box size="0.18 0.38 0.02"/>
      </geometry>
    </collision>
  </link>
  <gazebo reference="light_back_light">
    <material>Gazebo/White</material>
  </gazebo>
  <joint name="joint_light_back_height" type="prismatic">
    <parent link="mobile_base"/>
    <child link="light_back_height"/>
    <origin rpy="0.0 0.0 3.141592653589793" xyz="-0.33 0.0 0.25"/>
    <axis xyz="0 0 1"/>
    <limit effort="100.0" lower="-0.18" upper="0.15" velocity="1.0"/>
  </joint>
  <transmission name="light_back_height_transmission">
    <type>transmission_interface/SimpleTransmission</type>
    <joint name="joint_light_back_height">
      <hardwareInterface>hardware_interface/EffortJointInterface</hardwareInterface>
    </joint>
    <actuator name="light_back_height_actuator">
      <mechanicalReduction>1</mechanicalReduction>
    </actuator>
  </transmission>
  <joint name="joint_light_back_roll" type="revolute">
    <parent link="light_back_height"/>
    <child link="light_back_roll"/>
    <origin rpy="0.0 0.0 0.0" xyz="0.035 0.0 0.0"/>
    <axis xyz="1 0 0"/>
    <limit effort="20.0" lower="-3.141592653589793" upper="3.141592653589793" velocity="1.0"/>
  </joint>
  <transmission name="light_back_roll_transmission">
    <type>transmission_interface/SimpleTransmission</type>
    <joint name="joint_light_back_roll">
      <hardwareInterface>hardware_interface/EffortJointInterface</hardwareInterface>
    </joint>
    <actuator name="light_back_roll_actuator">
      <mechanicalReduction>1</mechanicalReduction>
    </actuator>
  </transmission>
  <joint name="joint_light_back_pitch" type="revolute">
    <parent link="light_back_roll"/>
    <child link="light_back"/>
    <origin rpy="0.0 0.0 0.0" xyz="0.0 0.0 0.0"/>
    <axis xyz="0 1 0"/>
    <limit effort="20.0" lower="-1.5707963267948966" upper="1.5707963267948966" velocity="1.0"/>
  </joint>
  <transmission name="light_back_pitch_transmission">
    <type>transmission_interface/SimpleTransmission</type>
    <joint name="joint_light_back_pitch">
      <hardwareInterface>hardware_interface/EffortJointInterface</hardwareInterface>
    </joint>
    <actuator name="light_back_pitch_actuator">
      <mechanicalReduction>1</mechanicalReduction>
    </actuator>
  </transmission>
  <joint name="joint_light_back_light_back_light" type="fixed">
    <parent link="light_back"/>
    <child link="light_back_light"/>
    <origin rpy="0.0 0.0 0.0" xyz="0.0 0.0 0.0"/>
  </joint>
  <gazebo reference="joint_light_back_light_back_light">
    <preserveFixedJoint>true</preserveFixedJoint>
  </gazebo>
  <link name="light_right_height">
    <inertial>
      <origin rpy="0.0 1.5707963267948966 0.0" xyz="-0.085 0.0 0.0"/>
      <mass value="0.09424777960769382"/>
      <inertia ixx="0.00046711555768063246" ixy="0.0" ixz="0.0" iyy="0.00046711555768063246" iyz="0.0" izz="2.9452431127404324e-05"/>
    </inertial>
    <visual>
      <origin rpy="0.0 1.5707963267948966 0.0" xyz="-0.085 0.0 0.0"/>
      <geometry>
        <cylinder length="0.24" radius="0.025"/>
      </geometry>
      <material name="Black"/>
    </visual>
    <collision>
      <origin rpy="0.0 1.5707963267948966 0.0" xyz="-0.085 0.0 0.0"/>
      <geometry>
        <cylinder length="0.24" radius="0.025"/>
      </geometry>
    </collision>
  </link>
  <gazebo reference="light_right_height">
    <material>Gazebo/Black</material>
  </gazebo>
  <link name="light_right_roll">
    <inertial>
      <origin rpy="0.0 0.0 0.0" xyz="0.0 0.0 0.0"/>
      <mass value="0.5222897786593033"/>
      <inertia ixx="0.00013057244466482584" ixy="0.0" ixz="0.0" iyy="0.00013057244466482584" iyz="0.0" izz="0.00013057244466482584"/>
    </inertial>
    <visual>
      <origin rpy="0.0 0.0 0.0" xyz="0.0 0.0 0.0"/>
      <geometry>
        <sphere radius="0.025"/>
      </geometry>
      <material name="Black"/>
    </visual>
    <collision>
      <origin rpy="0.0 0.0 0.0" xyz="0.0 0.0 0.0"/>
      <geometry>
        <sphere radius="0.025"/>
      </geometry>
    </collision>
  </link>
  <gazebo reference="light_right_roll">
    <material>Gazebo/Black</material>
  </gazebo>
  <link name="light_right">
    <inertial>
      <origin rpy="0.0 0.0 0.0" xyz="0.125 0.0 0.0"/>
      <mass value="0.8"/>
      <inertia ixx="0.010833333333333335" ixy="0.0" ixz="0.0" iyy="0.002833333333333334" iyz="0.0" izz="0.013333333333333336"/>
    </inertial>
    <visual>
      <origin rpy="0.0 0.0 0.0" xyz="0.125 0.0 0.0"/>
      <geometry>
        <box size="0.2 0.4 0.05"/>
      </geometry>
      <material name="Black"/>
    </visual>
    <collision>
      <origin rpy="0.0 0.0 0.0" xyz="0.125 0.0 0.0"/>
      <geometry>
        <box size="0.2 0.4 0.05"/>
      </geometry>
    </collision>
  </link>
  <gazebo reference="light_right">
    <material>Gazebo/Black</material>
  </gazebo>
  <link name="light_right_light">
    <inertial>
      <origin rpy="0.0 0.0 0.0" xyz="0.125 0.0 0.016"/>
      <mass value="0.2736"/>
      <inertia ixx="0.0033014400000000005" ixy="0.0" ixz="0.0" iyy="0.0007478399999999999" iyz="0.0" izz="0.0040310400000000005"/>
    </inertial>
    <visual>
      <origin rpy="0.0 0.0 0.0" xyz="0.125 0.0 0.016"/>
      <geometry>
        <box size="0.18 0.38 0.02"/>
      </geometry>
      <material name="White"/>
    </visual>
    <collision>
      <origin rpy="0.0 0.0 0.0" xyz="0.125 0.0 0.016"/>
      <geometry>
        <box size="0.18 0.38 0.02"/>
      </geometry>
    </collision>
  </link>
  <gazebo reference="light_right_light">
    <material>Gazebo/White</material>
  </gazebo>
  <joint name="joint_light_right_height" type="prismatic">
    <parent link="mobile_base"/>
    <child link="light_right_height"/>
    <origin rpy="0.0 0.0 -1.0471975511965976" xyz="0.16500000000000004 -0.28578838324886474 0.25"/>
    <axis xyz="0 0 1"/>
    <limit effort="100.0" lower="-0.18" upper="0.15" velocity="1.0"/>
  </joint>
  <transmission name="light_right_height_transmission">
    <type>transmission_interface/SimpleTransmission</type>
    <joint name="joint_light_right_height">
      <hardwareInterface>hardware_interface/EffortJointInterface</hardwareInterface>
    </joint>
    <actuator name="light_right_height_actuator">
      <mechanicalReduction>1</mechanicalReduction>
    </actuator>
  </transmission>
  <joint name="joint_light_right_roll" type="revolute">
    <parent link="light_right_height"/>
    <child link="light_right_roll"/>
    <origin rpy="0.0 0.0 0.0" xyz="0.035 0.0 0.0"/>
    <axis xyz="1 0 0"/>
    <limit effort="20.0" lower="-3.141592653589793" upper="3.141592653589793" velocity="1.0"/>
  </joint>
  <transmission name="light_right_roll_transmission">
    <type>transmission_interface/SimpleTransmission</type>
    <joint name="joint_light_right_roll">
      <hardwareInterface>hardware_interface/EffortJointInterface</hardwareInterface>
    </joint>
    <actuator name="light_right_roll_actuator">
      <mechanicalReduction>1</mechanicalReduction>
    </actuator>
  </transmission>
  <joint name="joint_light_right_pitch" type="revolute">
    <parent link="light_right_roll"/>
    <child link="light_right"/>
    <origin rpy="0.0 0.0 0.0" xyz="0.0 0.0 0.0"/>
    <axis xyz="0 1 0"/>
    <limit effort="20.0" lower="-1.5707963267948966" upper="1.5707963267948966" velocity="1.0"/>
  </joint>
  <transmission name="light_right_pitch_transmission">
    <type>transmission_interface/SimpleTransmission</type>
    <joint name="joint_light_right_pitch">
      <hardwareInterface>hardware_interface/EffortJointInterface</hardwareInterface>
    </joint>
    <actuator name="light_right_pitch_actuator">
      <mechanicalReduction>1</mechanicalReduction>
    </actuator>
  </transmission>
  <joint name="joint_light_right_light_right_light" type="fixed">
    <parent link="light_right"/>
    <child link="light_right_light"/>
    <origin rpy="0.0 0.0 0.0" xyz="0.0 0.0 0.0"/>
  </joint>
  <gazebo reference="joint_light_right_light_right_light">
    <preserveFixedJoint>true</preserveFixedJoint>
  </gazebo>
  <gazebo>
    <plugin filename="libgazebo_ros_control.so" name="gazebo_ros_control">
      <robotNamespace>/cleanbot</robotNamespace>
    </plugin>
  </gazebo>
</robot>

